<?xml version="1.0" encoding="utf-8"?>
<!-- This URDF was automatically created by SolidWorks to URDF Exporter! Originally created by Stephen Brawner (brawner@gmail.com) 
     Commit Version: 1.6.0-1-g15f4949  Build Version: 1.6.7594.29634
     For more information, please see http://wiki.ros.org/sw_urdf_exporter -->
<robot
  name="Robotkolum_description">
  <link
    name="base_link">
    <inertial>
      <origin
        xyz="-0.0547102512168774 -0.0539135962858282 0.293078473537296"
        rpy="0 0 0" />
      <mass
        value="2.51589336365614" />
      <inertia
        ixx="0.013365544099249"
        ixy="-4.93922040992719E-07"
        ixz="-1.03052367925609E-06"
        iyy="0.0157638550588336"
        iyz="-0.00128460025565426"
        izz="0.0107263365778983" />
    </inertial>
    <visual>
      <origin
        xyz="0 0 0"
        rpy="0 0 0" />
      <geometry>
        <mesh
          filename="package://Robotkolum_description/meshes/base_link.STL" />
      </geometry>
      <material
        name="">
        <color
          rgba="0.909803921568627 0.443137254901961 0.0313725490196078 1" />
      </material>
    </visual>
    <collision>
      <origin
        xyz="0 0 0"
        rpy="0 0 0" />
      <geometry>
        <mesh
          filename="package://Robotkolum_description/meshes/base_link.STL" />
      </geometry>
    </collision>
  </link>
  <link
    name="link1">
    <inertial>
      <origin
        xyz="-7.81303077790341E-11 0.0861397678778996 -2.77555756156289E-17"
        rpy="0 0 0" />
      <mass
        value="1.81433447277617" />
      <inertia
        ixx="0.0087933374527463"
        ixy="-3.96410536737438E-11"
        ixz="2.81930207911979E-10"
        iyy="0.00342156052453577"
        iyz="1.08200649583418E-16"
        izz="0.00962693155734595" />
    </inertial>
    <visual>
      <origin
        xyz="0 0 0"
        rpy="0 0 0" />
      <geometry>
        <mesh
          filename="package://Robotkolum_description/meshes/link1.STL" />
      </geometry>
      <material
        name="">
        <color
          rgba="0.909803921568627 0.443137254901961 0.0313725490196078 1" />
      </material>
    </visual>
    <collision>
      <origin
        xyz="0 0 0"
        rpy="0 0 0" />
      <geometry>
        <mesh
          filename="package://Robotkolum_description/meshes/link1.STL" />
      </geometry>
    </collision>
  </link>
  <joint
    name="joint1"
    type="continuous">
    <origin
      xyz="-0.054717 -0.2775 0"
      rpy="1.5708 0 -1.1167" />
    <parent
      link="base_link" />
    <child
      link="link1" />
    <axis
      xyz="0 1 0" />
  </joint>
  <link
    name="link2">
    <inertial>
      <origin
        xyz="6.15996356145843E-08 0.0788515417450465 8.77472552396341E-08"
        rpy="0 0 0" />
      <mass
        value="2.75822019148349" />
      <inertia
        ixx="0.0324988687301968"
        ixy="-2.06355301119246E-09"
        ixz="1.52013430489151E-10"
        iyy="0.0128720600190586"
        iyz="4.2413778895598E-08"
        izz="0.0222528491846646" />
    </inertial>
    <visual>
      <origin
        xyz="0 0 0"
        rpy="0 0 0" />
      <geometry>
        <mesh
          filename="package://Robotkolum_description/meshes/link2.STL" />
      </geometry>
      <material
        name="">
        <color
          rgba="0.909803921568627 0.443137254901961 0.0313725490196078 1" />
      </material>
    </visual>
    <collision>
      <origin
        xyz="0 0 0"
        rpy="0 0 0" />
      <geometry>
        <mesh
          filename="package://Robotkolum_description/meshes/link2.STL" />
      </geometry>
    </collision>
  </link>
  <joint
    name="joint2"
    type="continuous">
    <origin
      xyz="0 0.1476 0"
      rpy="0 0 0.31635" />
    <parent
      link="link1" />
    <child
      link="link2" />
    <axis
      xyz="0 0 1" />
  </joint>
  <link
    name="link3">
    <inertial>
      <origin
        xyz="0.0680929992532401 0.0605911001451526 -0.00499999962055384"
        rpy="0 0 0" />
      <mass
        value="1.5075090298851" />
      <inertia
        ixx="0.00235102664523115"
        ixy="-0.00124680201145731"
        ixz="-8.31426155136969E-12"
        iyy="0.0105751007141514"
        iyz="-2.51162291512634E-11"
        izz="0.0115855549701609" />
    </inertial>
    <visual>
      <origin
        xyz="0 0 0"
        rpy="0 0 0" />
      <geometry>
        <mesh
          filename="package://Robotkolum_description/meshes/link3.STL" />
      </geometry>
      <material
        name="">
        <color
          rgba="0.909803921568627 0.443137254901961 0.0313725490196078 1" />
      </material>
    </visual>
    <collision>
      <origin
        xyz="0 0 0"
        rpy="0 0 0" />
      <geometry>
        <mesh
          filename="package://Robotkolum_description/meshes/link3.STL" />
      </geometry>
    </collision>
  </link>
  <joint
    name="joint3"
    type="continuous">
    <origin
      xyz="0 0.25 0"
      rpy="0 0 -0.2744" />
    <parent
      link="link2" />
    <child
      link="link3" />
    <axis
      xyz="0 0 1" />
  </joint>
  <link
    name="link4">
    <inertial>
      <origin
        xyz="0.00885801209308046 -3.30423627348253E-09 -0.00499994413281765"
        rpy="0 0 0" />
      <mass
        value="0.139423912696039" />
      <inertia
        ixx="6.62498914250543E-05"
        ixy="1.05204211342766E-10"
        ixz="-1.46857144195758E-10"
        iyy="0.000167959127569208"
        iyz="-2.27020296240654E-10"
        izz="0.00018402625007639" />
    </inertial>
    <visual>
      <origin
        xyz="0 0 0"
        rpy="0 0 0" />
      <geometry>
        <mesh
          filename="package://Robotkolum_description/meshes/link4.STL" />
      </geometry>
      <material
        name="">
        <color
          rgba="0.729411764705882 0.356862745098039 0.0235294117647059 1" />
      </material>
    </visual>
    <collision>
      <origin
        xyz="0 0 0"
        rpy="0 0 0" />
      <geometry>
        <mesh
          filename="package://Robotkolum_description/meshes/link4.STL" />
      </geometry>
    </collision>
  </link>
  <joint
    name="joint4"
    type="continuous">
    <origin
      xyz="0.21373 0.0725 0"
      rpy="0 0 -0.038402" />
    <parent
      link="link3" />
    <child
      link="link4" />
    <axis
      xyz="0 0 1" />
  </joint>
</robot>