<?xml version="1.0" encoding="utf-8"?>
<!-- This URDF was automatically created by SolidWorks to URDF Exporter! Originally created by Stephen Brawner (brawner@gmail.com) 
     Commit Version: 1.6.0-1-g15f4949  Build Version: 1.6.7594.29634
     For more information, please see http://wiki.ros.org/sw_urdf_exporter -->
<robot
  name="TayGap">
  <link
    name="base_link">
    <inertial>
      <origin
        xyz="0.155089529965973 0.0891497928154382 0.106548243989106"
        rpy="0 0 0" />
      <mass
        value="27.154380119055" />
      <inertia
        ixx="0.128305251803877"
        ixy="-0.000131818581333414"
        ixz="-1.11496294415566E-05"
        iyy="0.119231744921295"
        iyz="0.000277151030321704"
        izz="0.0962057704956619" />
    </inertial>
    <visual>
      <origin
        xyz="0 0 0"
        rpy="0 0 0" />
      <geometry>
        <mesh
          filename="package://TayGap/meshes/base_link.STL" />
      </geometry>
      <material
        name="">
        <color
          rgba="0.776470588235294 0.756862745098039 0.737254901960784 1" />
      </material>
    </visual>
    <collision>
      <origin
        xyz="0 0 0"
        rpy="0 0 0" />
      <geometry>
        <mesh
          filename="package://TayGap/meshes/base_link.STL" />
      </geometry>
    </collision>
  </link>
  <link
    name="link_1">
    <inertial>
      <origin
        xyz="3.6563E-09 0.061786 0.15491"
        rpy="0 0 0" />
      <mass
        value="40.19" />
      <inertia
        ixx="0.50815"
        ixy="-1.6635E-09"
        ixz="8.2183E-09"
        iyy="0.50975"
        iyz="-0.033417"
        izz="0.12975" />
    </inertial>
    <visual>
      <origin
        xyz="0 0 0"
        rpy="0 0 0" />
      <geometry>
        <mesh
          filename="package://TayGap/meshes/link_1.STL" />
      </geometry>
      <material
        name="">
        <color
          rgba="0.77647 0.75686 0.73725 1" />
      </material>
    </visual>
    <collision>
      <origin
        xyz="0 0 0"
        rpy="0 0 0" />
      <geometry>
        <mesh
          filename="package://TayGap/meshes/link_1.STL" />
      </geometry>
    </collision>
  </link>
  <joint
    name="joint_1"
    type="continuous">
    <origin
      xyz="0.15509 -0.10565 0.14236"
      rpy="1.5708 0 3.0517" />
    <parent
      link="base_link" />
    <child
      link="link_1" />
    <axis
      xyz="0 1 0" />
  </joint>
  <link
    name="link_2">
    <inertial>
      <origin
        xyz="-3.4462E-08 0.12413 0.20373"
        rpy="0 0 0" />
      <mass
        value="118.94" />
      <inertia
        ixx="2.7618"
        ixy="8.7947E-06"
        ixz="4.7526E-08"
        iyy="2.3197"
        iyz="0.17283"
        izz="0.86325" />
    </inertial>
    <visual>
      <origin
        xyz="0 0 0"
        rpy="0 0 0" />
      <geometry>
        <mesh
          filename="package://TayGap/meshes/link_2.STL" />
      </geometry>
      <material
        name="">
        <color
          rgba="0.77647 0.75686 0.73725 1" />
      </material>
    </visual>
    <collision>
      <origin
        xyz="0 0 0"
        rpy="0 0 0" />
      <geometry>
        <mesh
          filename="package://TayGap/meshes/link_2.STL" />
      </geometry>
    </collision>
  </link>
  <joint
    name="joint_2"
    type="continuous">
    <origin
      xyz="0 0.094021 0.25"
      rpy="0 0.23991 0" />
    <parent
      link="link_1" />
    <child
      link="link_2" />
    <axis
      xyz="0 1 0" />
  </joint>
  <link
    name="link_3">
    <inertial>
      <origin
        xyz="-1.1102E-16 0 -0.077498"
        rpy="0 0 0" />
      <mass
        value="1.4255" />
      <inertia
        ixx="0.051417"
        ixy="0"
        ixz="-8.7334E-19"
        iyy="0.051417"
        iyz="-1.6922E-18"
        izz="0.00069051" />
    </inertial>
    <visual>
      <origin
        xyz="0 0 0"
        rpy="0 0 0" />
      <geometry>
        <mesh
          filename="package://TayGap/meshes/link_3.STL" />
      </geometry>
      <material
        name="">
        <color
          rgba="1 1 1 1" />
      </material>
    </visual>
    <collision>
      <origin
        xyz="0 0 0"
        rpy="0 0 0" />
      <geometry>
        <mesh
          filename="package://TayGap/meshes/link_3.STL" />
      </geometry>
    </collision>
  </link>
  <joint
    name="joint_3"
    type="prismatic">
    <origin
      xyz="0 0 0.40562"
      rpy="-1.5708 -0.85267 3.1416" />
    <parent
      link="link_2" />
    <child
      link="link_3" />
    <axis
      xyz="0 0 1" />
    <limit
      lower="0"
      upper="0"
      effort="0"
      velocity="0" />
  </joint>
</robot>