<?xml version="1.0" encoding="utf-8"?>
<!-- This URDF was automatically created by SolidWorks to URDF Exporter! Originally created by Stephen Brawner (brawner@gmail.com) 
     Commit Version: 1.6.0-1-g15f4949  Build Version: 1.6.7594.29634
     For more information, please see http://wiki.ros.org/sw_urdf_exporter -->
<robot
  name="UET_discription">
  <link
    name="base_link">
    <inertial>
      <origin
        xyz="0.0065983702120464 -0.0257427295708328 0.336373566912517"
        rpy="0 0 0" />
      <mass
        value="2.13775890794895" />
      <inertia
        ixx="0.0447028692836465"
        ixy="-2.94763553843355E-07"
        ixz="2.53128621951429E-05"
        iyy="0.0447043656015194"
        iyz="-8.94085734844152E-06"
        izz="0.00543037915506856" />
    </inertial>
    <visual>
      <origin
        xyz="0 0 0"
        rpy="0 0 0" />
      <geometry>
        <mesh
          filename="package://UET_discription/meshes/base_link.STL" />
      </geometry>
      <material
        name="">
        <color
          rgba="0.792156862745098 0.819607843137255 0.933333333333333 1" />
      </material>
    </visual>
    <collision>
      <origin
        xyz="0 0 0"
        rpy="0 0 0" />
      <geometry>
        <mesh
          filename="package://UET_discription/meshes/base_link.STL" />
      </geometry>
    </collision>
  </link>
  <link
    name="link_1">
    <inertial>
      <origin
        xyz="-8.67361737988404E-19 -0.0718597871210987 0.0268557087493879"
        rpy="0 0 0" />
      <mass
        value="0.979766055196368" />
      <inertia
        ixx="0.00747669548599809"
        ixy="-1.22078307926861E-19"
        ixz="-9.57416633403933E-21"
        iyy="0.00122674898370894"
        iyz="-3.56275974428907E-06"
        izz="0.00814613143305283" />
    </inertial>
    <visual>
      <origin
        xyz="0 0 0"
        rpy="0 0 0" />
      <geometry>
        <mesh
          filename="package://UET_discription/meshes/link_1.STL" />
      </geometry>
      <material
        name="">
        <color
          rgba="0.501960784313725 0.501960784313725 1 1" />
      </material>
    </visual>
    <collision>
      <origin
        xyz="0 0 0"
        rpy="0 0 0" />
      <geometry>
        <mesh
          filename="package://UET_discription/meshes/link_1.STL" />
      </geometry>
    </collision>
  </link>
  <joint
    name="joint_1"
    type="prismatic">
    <origin
      xyz="0.0066366 -0.563 -0.025756"
      rpy="1.5708 0 0" />
    <parent
      link="base_link" />
    <child
      link="link_1" />
    <axis
      xyz="0 0 1" />
    <limit
      lower="0"
      upper="0.25"
      effort="0"
      velocity="0" />
  </joint>
  <link
    name="link_2">
    <inertial>
      <origin
        xyz="2.77555756156289E-17 -0.111115906260767 0.0149039187770865"
        rpy="0 0 0" />
      <mass
        value="0.735688332874957" />
      <inertia
        ixx="0.00703986564925121"
        ixy="1.30104260698261E-18"
        ixz="-3.67929936463587E-20"
        iyy="0.000681755118576011"
        iyz="-9.81408755090606E-07"
        izz="0.00758188394305661" />
    </inertial>
    <visual>
      <origin
        xyz="0 0 0"
        rpy="0 0 0" />
      <geometry>
        <mesh
          filename="package://UET_discription/meshes/link_2.STL" />
      </geometry>
      <material
        name="">
        <color
          rgba="0.501960784313725 0.501960784313725 1 1" />
      </material>
    </visual>
    <collision>
      <origin
        xyz="0 0 0"
        rpy="0 0 0" />
      <geometry>
        <mesh
          filename="package://UET_discription/meshes/link_2.STL" />
      </geometry>
    </collision>
  </link>
  <joint
    name="joint_2"
    type="continuous">
    <origin
      xyz="0 -0.20072 0.012"
      rpy="0 0 0.99553" />
    <parent
      link="link_1" />
    <child
      link="link_2" />
    <axis
      xyz="0 0 1" />
  </joint>
  <link
    name="link_3">
    <inertial>
      <origin
        xyz="2.77555756156289E-17 -0.0858630761090732 0.015"
        rpy="0 0 0" />
      <mass
        value="0.46058799788846" />
      <inertia
        ixx="0.00330258197825701"
        ixy="2.15201552356455E-19"
        ixz="-1.54365406658549E-20"
        iyy="0.000523672756561597"
        iyz="-1.19153988457126E-19"
        izz="0.00357603273485006" />
    </inertial>
    <visual>
      <origin
        xyz="0 0 0"
        rpy="0 0 0" />
      <geometry>
        <mesh
          filename="package://UET_discription/meshes/link_3.STL" />
      </geometry>
      <material
        name="">
        <color
          rgba="0.501960784313725 0.501960784313725 1 1" />
      </material>
    </visual>
    <collision>
      <origin
        xyz="0 0 0"
        rpy="0 0 0" />
      <geometry>
        <mesh
          filename="package://UET_discription/meshes/link_3.STL" />
      </geometry>
    </collision>
  </link>
  <joint
    name="joint_3"
    type="continuous">
    <origin
      xyz="0 -0.25 0"
      rpy="0 0 -0.99553" />
    <parent
      link="link_2" />
    <child
      link="link_3" />
    <axis
      xyz="0 0 1" />
  </joint>
</robot>