<?xml version="1.0" encoding="utf-8"?>
<!-- This URDF was automatically created by SolidWorks to URDF Exporter! Originally created by Stephen Brawner (brawner@gmail.com) 
     Commit Version: 1.6.0-1-g15f4949  Build Version: 1.6.7594.29634
     For more information, please see http://wiki.ros.org/sw_urdf_exporter -->
<robot
  name="SLDASM">
  <link
    name="base_link">
    <inertial>
      <origin
        xyz="0.0065983702120464 -0.336373566912517 -0.0257427295708327"
        rpy="0 0 0" />
      <mass
        value="2.13775890794895" />
      <inertia
        ixx="0.0447028692836465"
        ixy="-2.53128621951427E-05"
        ixz="-2.94763553843353E-07"
        iyy="0.00543037915506856"
        iyz="8.94085734844418E-06"
        izz="0.0447043656015194" />
    </inertial>
    <visual>
      <origin
        xyz="0 0 0"
        rpy="0 0 0" />
      <geometry>
        <mesh
          filename="package://SLDASM/meshes/base_link.STL" />
      </geometry>
      <material
        name="">
        <color
          rgba="0.792156862745098 0.819607843137255 0.933333333333333 1" />
      </material>
    </visual>
    <collision>
      <origin
        xyz="0 0 0"
        rpy="0 0 0" />
      <geometry>
        <mesh
          filename="package://SLDASM/meshes/base_link.STL" />
      </geometry>
    </collision>
  </link>
  <link
    name="link_1">
    <inertial>
      <origin
        xyz="-1.38777878078145E-17 -0.0718597871210987 -0.220409660211877"
        rpy="0 0 0" />
      <mass
        value="0.979766055196368" />
      <inertia
        ixx="0.0074766954859981"
        ixy="6.78328921579028E-21"
        ixz="-4.6096174513509E-20"
        iyy="0.00122674898370894"
        iyz="-3.56275974428907E-06"
        izz="0.00814613143305283" />
    </inertial>
    <visual>
      <origin
        xyz="0 0 0"
        rpy="0 0 0" />
      <geometry>
        <mesh
          filename="package://SLDASM/meshes/link_1.STL" />
      </geometry>
      <material
        name="">
        <color
          rgba="0.501960784313725 0.501960784313725 1 1" />
      </material>
    </visual>
    <collision>
      <origin
        xyz="0 0 0"
        rpy="0 0 0" />
      <geometry>
        <mesh
          filename="package://SLDASM/meshes/link_1.STL" />
      </geometry>
    </collision>
  </link>
  <joint
    name="joint_1"
    type="prismatic">
    <origin
      xyz="0.0066366 -0.563 -0.025756"
      rpy="1.5708 0 0" />
    <parent
      link="base_link" />
    <child
      link="link_1" />
    <axis
      xyz="0 0 1" />
    <limit
      lower="0"
      upper="0.03"
      effort="0"
      velocity="0" />
  </joint>
  <link
    name="link_2">
    <inertial>
      <origin
        xyz="0 -0.111115906260767 -0.232361450184178"
        rpy="0 0 0" />
      <mass
        value="0.735688332874956" />
      <inertia
        ixx="0.0070398656492512"
        ixy="7.58941520739853E-19"
        ixz="-5.79158777685128E-20"
        iyy="0.00068175511857601"
        iyz="-9.81408755089889E-07"
        izz="0.0075818839430566" />
    </inertial>
    <visual>
      <origin
        xyz="0 0 0"
        rpy="0 0 0" />
      <geometry>
        <mesh
          filename="package://SLDASM/meshes/link_2.STL" />
      </geometry>
      <material
        name="">
        <color
          rgba="0.501960784313725 0.501960784313725 1 1" />
      </material>
    </visual>
    <collision>
      <origin
        xyz="0 0 0"
        rpy="0 0 0" />
      <geometry>
        <mesh
          filename="package://SLDASM/meshes/link_2.STL" />
      </geometry>
    </collision>
  </link>
  <joint
    name="joint_2"
    type="continuous">
    <origin
      xyz="0 -0.200720396700335 0.012"
      rpy="0 0 0.995527576712073" />
    <parent
      link="link_1" />
    <child
      link="link_2" />
    <axis
      xyz="0 0 1" />
  </joint>
  <link
    name="link_3">
    <inertial>
      <origin
        xyz="0 -0.0858630761090733 -0.232265368961265"
        rpy="0 0 0" />
      <mass
        value="0.460587997888459" />
      <inertia
        ixx="0.00330258197825701"
        ixy="9.31934798485548E-19"
        ixz="-1.36543554243177E-20"
        iyy="0.000523672756561596"
        iyz="2.17589235236408E-19"
        izz="0.00357603273485007" />
    </inertial>
    <visual>
      <origin
        xyz="0 0 0"
        rpy="0 0 0" />
      <geometry>
        <mesh
          filename="package://SLDASM/meshes/link_3.STL" />
      </geometry>
      <material
        name="">
        <color
          rgba="0.501960784313725 0.501960784313725 1 1" />
      </material>
    </visual>
    <collision>
      <origin
        xyz="0 0 0"
        rpy="0 0 0" />
      <geometry>
        <mesh
          filename="package://SLDASM/meshes/link_3.STL" />
      </geometry>
    </collision>
  </link>
  <joint
    name="joint_3"
    type="continuous">
    <origin
      xyz="0 -0.25 0"
      rpy="0 0 -0.995527576712073" />
    <parent
      link="link_2" />
    <child
      link="link_3" />
    <axis
      xyz="0 0 1" />
  </joint>
</robot>