<?xml version="1.0" encoding="utf-8"?>
<!-- This URDF was automatically created by SolidWorks to URDF Exporter! Originally created by Stephen Brawner (brawner@gmail.com) 
     Commit Version: 1.6.0-1-g15f4949  Build Version: 1.6.7594.29634
     For more information, please see http://wiki.ros.org/sw_urdf_exporter -->
<robot
  name="Scara_Discription">
  <link
    name="base_link">
    <inertial>
      <origin
        xyz="0.0065984 -0.33637 -0.025743"
        rpy="0 0 0" />
      <mass
        value="2.1378" />
      <inertia
        ixx="0.044703"
        ixy="-2.5313E-05"
        ixz="-2.9476E-07"
        iyy="0.0054304"
        iyz="8.9409E-06"
        izz="0.044704" />
    </inertial>
    <visual>
      <origin
        xyz="0 0 0"
        rpy="0 0 0" />
      <geometry>
        <mesh
          filename="package://Scara_Discription/meshes/base_link.STL" />
      </geometry>
      <material
        name="">
        <color
          rgba="0.79216 0.81961 0.93333 1" />
      </material>
    </visual>
    <collision>
      <origin
        xyz="0 0 0"
        rpy="0 0 0" />
      <geometry>
        <mesh
          filename="package://Scara_Discription/meshes/base_link.STL" />
      </geometry>
    </collision>
  </link>
  <link
    name="link_1">
    <inertial>
      <origin
        xyz="-1.4745E-17 -0.07186 -0.22041"
        rpy="0 0 0" />
      <mass
        value="0.97977" />
      <inertia
        ixx="0.0074767"
        ixy="5.9486E-21"
        ixz="-4.6092E-20"
        iyy="0.0012267"
        iyz="-3.5628E-06"
        izz="0.0081461" />
    </inertial>
    <visual>
      <origin
        xyz="0 0 0"
        rpy="0 0 0" />
      <geometry>
        <mesh
          filename="package://Scara_Discription/meshes/link_1.STL" />
      </geometry>
      <material
        name="">
        <color
          rgba="0.50196 0.50196 1 1" />
      </material>
    </visual>
    <collision>
      <origin
        xyz="0 0 0"
        rpy="0 0 0" />
      <geometry>
        <mesh
          filename="package://Scara_Discription/meshes/link_1.STL" />
      </geometry>
    </collision>
  </link>
  <joint
    name="joint_1"
    type="prismatic">
    <origin
      xyz="0.0066366 -0.563 -0.025756"
      rpy="1.5708 0 0" />
    <parent
      link="base_link" />
    <child
      link="link_1" />
    <axis
      xyz="0 0 1" />
    <limit
      lower="0"
      upper="0.25"
      effort="0"
      velocity="0" />
  </joint>
  <link
    name="link_2">
    <inertial>
      <origin
        xyz="0 -0.11112 -0.23236"
        rpy="0 0 0" />
      <mass
        value="0.73569" />
      <inertia
        ixx="0.0070399"
        ixy="3.7947E-19"
        ixz="-6.5592E-20"
        iyy="0.00068176"
        iyz="-9.8141E-07"
        izz="0.0075819" />
    </inertial>
    <visual>
      <origin
        xyz="0 0 0"
        rpy="0 0 0" />
      <geometry>
        <mesh
          filename="package://Scara_Discription/meshes/link_2.STL" />
      </geometry>
      <material
        name="">
        <color
          rgba="0.50196 0.50196 1 1" />
      </material>
    </visual>
    <collision>
      <origin
        xyz="0 0 0"
        rpy="0 0 0" />
      <geometry>
        <mesh
          filename="package://Scara_Discription/meshes/link_2.STL" />
      </geometry>
    </collision>
  </link>
  <joint
    name="joint_2"
    type="revolute">
    <origin
      xyz="0 -0.20072 0.012"
      rpy="0 0 0.99553" />
    <parent
      link="link_1" />
    <child
      link="link_2" />
    <axis
      xyz="0 0 1" />
    <limit
      lower="0"
      upper="0"
      effort="0"
      velocity="0" />
  </joint>
  <link
    name="link_3">
    <inertial>
      <origin
        xyz="0 -0.085863 -0.23227"
        rpy="0 0 0" />
      <mass
        value="0.46059" />
      <inertia
        ixx="0.0033026"
        ixy="9.0439E-19"
        ixz="-5.5887E-21"
        iyy="0.00052367"
        iyz="2.2513E-19"
        izz="0.003576" />
    </inertial>
    <visual>
      <origin
        xyz="0 0 0"
        rpy="0 0 0" />
      <geometry>
        <mesh
          filename="package://Scara_Discription/meshes/link_3.STL" />
      </geometry>
      <material
        name="">
        <color
          rgba="0.50196 0.50196 1 1" />
      </material>
    </visual>
    <collision>
      <origin
        xyz="0 0 0"
        rpy="0 0 0" />
      <geometry>
        <mesh
          filename="package://Scara_Discription/meshes/link_3.STL" />
      </geometry>
    </collision>
  </link>
  <joint
    name="joint_3"
    type="revolute">
    <origin
      xyz="0 -0.25 0"
      rpy="0 0 -0.99553" />
    <parent
      link="link_2" />
    <child
      link="link_3" />
    <axis
      xyz="0 0 1" />
    <limit
      lower="0"
      upper="0"
      effort="0"
      velocity="0" />
  </joint>
</robot>