<?xml version="1.0" encoding="utf-8"?>
<!-- This URDF was automatically created by SolidWorks to URDF Exporter! Originally created by Stephen Brawner (brawner@gmail.com) 
     Commit Version: 1.6.0-1-g15f4949  Build Version: 1.6.7594.29634
     For more information, please see http://wiki.ros.org/sw_urdf_exporter -->
<robot
  name="Tay_Gap_Scara">
  <link
    name="base_link">
    <inertial>
      <origin
        xyz="0.0065984 -0.33637 -0.025743"
        rpy="0 0 0" />
      <mass
        value="2.1378" />
      <inertia
        ixx="0.044703"
        ixy="-2.5313E-05"
        ixz="-2.9476E-07"
        iyy="0.0054304"
        iyz="8.9409E-06"
        izz="0.044704" />
    </inertial>
    <visual>
      <origin
        xyz="0 0 0"
        rpy="0 0 0" />
      <geometry>
        <mesh
          filename="package://Tay_Gap_Scara/meshes/base_link.STL" />
      </geometry>
      <material
        name="">
        <color
          rgba="0.79216 0.81961 0.93333 1" />
      </material>
    </visual>
    <collision>
      <origin
        xyz="0 0 0"
        rpy="0 0 0" />
      <geometry>
        <mesh
          filename="package://Tay_Gap_Scara/meshes/base_link.STL" />
      </geometry>
    </collision>
  </link>
  <link
    name="link_1">
    <inertial>
      <origin
        xyz="-2.6021E-18 -0.07186 -0.22314"
        rpy="0 0 0" />
      <mass
        value="0.97977" />
      <inertia
        ixx="0.0074767"
        ixy="-1.3563E-19"
        ixz="-9.5216E-21"
        iyy="0.0012267"
        iyz="-3.5628E-06"
        izz="0.0081461" />
    </inertial>
    <visual>
      <origin
        xyz="0 0 0"
        rpy="0 0 0" />
      <geometry>
        <mesh
          filename="package://Tay_Gap_Scara/meshes/link_1.STL" />
      </geometry>
      <material
        name="">
        <color
          rgba="0.50196 0.50196 1 1" />
      </material>
    </visual>
    <collision>
      <origin
        xyz="0 0 0"
        rpy="0 0 0" />
      <geometry>
        <mesh
          filename="package://Tay_Gap_Scara/meshes/link_1.STL" />
      </geometry>
    </collision>
  </link>
  <joint
    name="joint_1"
    type="prismatic">
    <origin
      xyz="0.0066366 -0.563 -0.025756"
      rpy="1.5708 0 0" />
    <parent
      link="base_link" />
    <child
      link="link_1" />
    <axis
      xyz="0 0 1" />
    <limit
      lower="-0.25"
      upper="0"
      effort="0"
      velocity="0" />
  </joint>
  <link
    name="link_2">
    <inertial>
      <origin
        xyz="5.55111512312578E-17 -0.111115906260767 -0.235096081222913"
        rpy="0 0 0" />
      <mass
        value="0.735688332874957" />
      <inertia
        ixx="0.0070398656492512"
        ixy="5.96311194867027E-19"
        ixz="-4.99220043288003E-20"
        iyy="0.000681755118576011"
        iyz="-9.8140875508998E-07"
        izz="0.0075818839430566" />
    </inertial>
    <visual>
      <origin
        xyz="0 0 0"
        rpy="0 0 0" />
      <geometry>
        <mesh
          filename="package://Tay_Gap_Scara/meshes/link_2.STL" />
      </geometry>
      <material
        name="">
        <color
          rgba="0.501960784313725 0.501960784313725 1 1" />
      </material>
    </visual>
    <collision>
      <origin
        xyz="0 0 0"
        rpy="0 0 0" />
      <geometry>
        <mesh
          filename="package://Tay_Gap_Scara/meshes/link_2.STL" />
      </geometry>
    </collision>
  </link>
  <joint
    name="joint_2"
    type="continuous">
    <origin
      xyz="0 -0.20072 0.012"
      rpy="0 0 0.99553" />
    <parent
      link="link_1" />
    <child
      link="link_2" />
    <axis
      xyz="0 0 1" />
  </joint>
  <link
    name="link_3">
    <inertial>
      <origin
        xyz="0 -0.085863 -0.235"
        rpy="0 0 0" />
      <mass
        value="0.46059" />
      <inertia
        ixx="0.0033026"
        ixy="5.9539E-19"
        ixz="-1.8324E-20"
        iyy="0.00052367"
        iyz="-1.8265E-19"
        izz="0.003576" />
    </inertial>
    <visual>
      <origin
        xyz="0 0 0"
        rpy="0 0 0" />
      <geometry>
        <mesh
          filename="package://Tay_Gap_Scara/meshes/link_3.STL" />
      </geometry>
      <material
        name="">
        <color
          rgba="0.50196 0.50196 1 1" />
      </material>
    </visual>
    <collision>
      <origin
        xyz="0 0 0"
        rpy="0 0 0" />
      <geometry>
        <mesh
          filename="package://Tay_Gap_Scara/meshes/link_3.STL" />
      </geometry>
    </collision>
  </link>
  <joint
    name="joint_3"
    type="continuous">
    <origin
      xyz="0 -0.25 0"
      rpy="0 0 -0.99553" />
    <parent
      link="link_2" />
    <child
      link="link_3" />
    <axis
      xyz="0 0 1" />
  </joint>
</robot>