<?xml version="1.0" encoding="utf-8"?>
<!-- This URDF was automatically created by SolidWorks to URDF Exporter! Originally created by Stephen Brawner (brawner@gmail.com) 
     Commit Version: 1.6.0-1-g15f4949  Build Version: 1.6.7594.29634
     For more information, please see http://wiki.ros.org/sw_urdf_exporter -->
<robot
  name="Tay_Gap_Discription">
  <link
    name="base_link">
    <inertial>
      <origin
        xyz="0.0065983702120464 -0.0257427295708328 0.336373566912517"
        rpy="0 0 0" />
      <mass
        value="2.13775890794895" />
      <inertia
        ixx="0.0447028692836465"
        ixy="-2.94763553843342E-07"
        ixz="2.53128621951432E-05"
        iyy="0.0447043656015194"
        iyz="-8.9408573484417E-06"
        izz="0.00543037915506856" />
    </inertial>
    <visual>
      <origin
        xyz="0 0 0"
        rpy="0 0 0" />
      <geometry>
        <mesh
          filename="package://Tay_Gap_Discription/meshes/base_link.STL" />
      </geometry>
      <material
        name="">
        <color
          rgba="0.792156862745098 0.819607843137255 0.933333333333333 1" />
      </material>
    </visual>
    <collision>
      <origin
        xyz="0 0 0"
        rpy="0 0 0" />
      <geometry>
        <mesh
          filename="package://Tay_Gap_Discription/meshes/base_link.STL" />
      </geometry>
    </collision>
  </link>
  <link
    name="link_1">
    <inertial>
      <origin
        xyz="-8.67361737988404E-19 -0.0718597871210987 0.026855708749388"
        rpy="0 0 0" />
      <mass
        value="0.979766055196368" />
      <inertia
        ixx="0.00747669548599809"
        ixy="-2.7998259415945E-20"
        ixz="-3.45796309842999E-20"
        iyy="0.00122674898370894"
        iyz="-3.56275974428905E-06"
        izz="0.00814613143305283" />
    </inertial>
    <visual>
      <origin
        xyz="0 0 0"
        rpy="0 0 0" />
      <geometry>
        <mesh
          filename="package://Tay_Gap_Discription/meshes/link_1.STL" />
      </geometry>
      <material
        name="">
        <color
          rgba="0.501960784313725 0.501960784313725 1 1" />
      </material>
    </visual>
    <collision>
      <origin
        xyz="0 0 0"
        rpy="0 0 0" />
      <geometry>
        <mesh
          filename="package://Tay_Gap_Discription/meshes/link_1.STL" />
      </geometry>
    </collision>
  </link>
  <joint
    name="joint_1"
    type="prismatic">
    <origin
      xyz="0.0066366 -0.35931 -0.025756"
      rpy="1.5708 0 0" />
    <parent
      link="base_link" />
    <child
      link="link_1" />
    <axis
      xyz="0 0 1" />
    <limit
      lower="-0.20369"
      upper="0.046314"
      effort="0"
      velocity="0" />
  </joint>
  <link
    name="link_2">
    <inertial>
      <origin
        xyz="-2.77555756156289E-17 -0.111115906260767 0.0149039187770866"
        rpy="0 0 0" />
      <mass
        value="0.735688332874957" />
      <inertia
        ixx="0.0070398656492512"
        ixy="-3.11708124589583E-18"
        ixz="-3.77988452712232E-20"
        iyy="0.000681755118576011"
        iyz="-9.814087550909E-07"
        izz="0.0075818839430566" />
    </inertial>
    <visual>
      <origin
        xyz="0 0 0"
        rpy="0 0 0" />
      <geometry>
        <mesh
          filename="package://Tay_Gap_Discription/meshes/link_2.STL" />
      </geometry>
      <material
        name="">
        <color
          rgba="0.501960784313725 0.501960784313725 1 1" />
      </material>
    </visual>
    <collision>
      <origin
        xyz="0 0 0"
        rpy="0 0 0" />
      <geometry>
        <mesh
          filename="package://Tay_Gap_Discription/meshes/link_2.STL" />
      </geometry>
    </collision>
  </link>
  <joint
    name="joint_2"
    type="continuous">
    <origin
      xyz="0 -0.20072 0.012"
      rpy="0 0 -0.59257" />
    <parent
      link="link_1" />
    <child
      link="link_2" />
    <axis
      xyz="0 0 1" />
  </joint>
  <link
    name="link_3">
    <inertial>
      <origin
        xyz="2.77555756156289E-16 -0.0870505907540813 0.0150000000000001"
        rpy="0 0 0" />
      <mass
        value="0.454304812581279" />
      <inertia
        ixx="0.00324975443379465"
        ixy="-9.52522430505351E-17"
        ixz="-1.79711265192459E-20"
        iyy="0.000517808450274895"
        iyz="-3.15377103999725E-20"
        izz="0.00352875533740904" />
    </inertial>
    <visual>
      <origin
        xyz="0 0 0"
        rpy="0 0 0" />
      <geometry>
        <mesh
          filename="package://Tay_Gap_Discription/meshes/link_3.STL" />
      </geometry>
      <material
        name="">
        <color
          rgba="0.501960784313725 0.501960784313725 1 1" />
      </material>
    </visual>
    <collision>
      <origin
        xyz="0 0 0"
        rpy="0 0 0" />
      <geometry>
        <mesh
          filename="package://Tay_Gap_Discription/meshes/link_3.STL" />
      </geometry>
    </collision>
  </link>
  <joint
    name="joint_3"
    type="continuous">
    <origin
      xyz="0 -0.25 0"
      rpy="0 0 -0.99443" />
    <parent
      link="link_2" />
    <child
      link="link_3" />
    <axis
      xyz="0 0 1" />
  </joint>
  <link
    name="linh_4">
    <inertial>
      <origin
        xyz="0.024711813445236 -2.77555756156289E-17 0"
        rpy="0 0 0" />
      <mass
        value="0.232492314942096" />
      <inertia
        ixx="7.02011095564576E-05"
        ixy="1.75282168077834E-20"
        ixz="5.70077452303869E-20"
        iyy="0.000387194299609599"
        iyz="0"
        izz="0.000387194299609599" />
    </inertial>
    <visual>
      <origin
        xyz="0 0 0"
        rpy="0 0 0" />
      <geometry>
        <mesh
          filename="package://Tay_Gap_Discription/meshes/linh_4.STL" />
      </geometry>
      <material
        name="">
        <color
          rgba="1 1 1 1" />
      </material>
    </visual>
    <collision>
      <origin
        xyz="0 0 0"
        rpy="0 0 0" />
      <geometry>
        <mesh
          filename="package://Tay_Gap_Discription/meshes/linh_4.STL" />
      </geometry>
    </collision>
  </link>
  <joint
    name="joint_4"
    type="continuous">
    <origin
      xyz="0 -0.2 0"
      rpy="0.75127 -1.5708 0" />
    <parent
      link="link_3" />
    <child
      link="linh_4" />
    <axis
      xyz="1 0 0" />
  </joint>
</robot>