<?xml version="1.0" encoding="utf-8"?>
<!-- This URDF was automatically created by SolidWorks to URDF Exporter! Originally created by Stephen Brawner (brawner@gmail.com) 
     Commit Version: 1.6.0-1-g15f4949  Build Version: 1.6.7594.29634
     For more information, please see http://wiki.ros.org/sw_urdf_exporter -->
<robot
  name="Ca_chua_discription">
  <link
    name="base_link">
    <inertial>
      <origin
        xyz="0.0065983702120464 -0.336373566912517 -0.0257427295708327"
        rpy="0 0 0" />
      <mass
        value="2.13775890794895" />
      <inertia
        ixx="0.0447028692836465"
        ixy="-2.53128621951427E-05"
        ixz="-2.94763553843357E-07"
        iyy="0.00543037915506856"
        iyz="8.94085734844386E-06"
        izz="0.0447043656015194" />
    </inertial>
    <visual>
      <origin
        xyz="0 0 0"
        rpy="0 0 0" />
      <geometry>
        <mesh
          filename="package://Ca_chua_discription/meshes/base_link.STL" />
      </geometry>
      <material
        name="">
        <color
          rgba="0.792156862745098 0.819607843137255 0.933333333333333 1" />
      </material>
    </visual>
    <collision>
      <origin
        xyz="0 0 0"
        rpy="0 0 0" />
      <geometry>
        <mesh
          filename="package://Ca_chua_discription/meshes/base_link.STL" />
      </geometry>
    </collision>
  </link>
  <link
    name="link_1">
    <inertial>
      <origin
        xyz="8.67361737988404E-19 -0.0718597871210987 -0.0194578791046949"
        rpy="0 0 0" />
      <mass
        value="0.979766055196368" />
      <inertia
        ixx="0.00747669548599809"
        ixy="-1.15725353931764E-19"
        ixz="-9.64382863124498E-21"
        iyy="0.00122674898370894"
        iyz="-3.56275974428906E-06"
        izz="0.00814613143305283" />
    </inertial>
    <visual>
      <origin
        xyz="0 0 0"
        rpy="0 0 0" />
      <geometry>
        <mesh
          filename="package://Ca_chua_discription/meshes/link_1.STL" />
      </geometry>
      <material
        name="">
        <color
          rgba="0.501960784313725 0.501960784313725 1 1" />
      </material>
    </visual>
    <collision>
      <origin
        xyz="0 0 0"
        rpy="0 0 0" />
      <geometry>
        <mesh
          filename="package://Ca_chua_discription/meshes/link_1.STL" />
      </geometry>
    </collision>
  </link>
  <joint
    name="joint_1"
    type="prismatic">
    <origin
      xyz="0.0066366 -0.35931 -0.025756"
      rpy="1.5708 0 0" />
    <parent
      link="base_link" />
    <child
      link="link_1" />
    <axis
      xyz="0 0 1" />
    <limit
      lower="-0.25"
      upper="0"
      effort="0"
      velocity="0" />
  </joint>
  <link
    name="link_2">
    <inertial>
      <origin
        xyz="-0.0548425804399554 -0.0966386878782949 -0.0314096690769962"
        rpy="0 0 0" />
      <mass
        value="0.735688332874956" />
      <inertia
        ixx="0.00549100848152213"
        ixy="-0.00272925750756946"
        ixz="-4.84385993030019E-07"
        iyy="0.00223061228630509"
        iyz="-8.53541653538469E-07"
        izz="0.0075818839430566" />
    </inertial>
    <visual>
      <origin
        xyz="0 0 0"
        rpy="0 0 0" />
      <geometry>
        <mesh
          filename="package://Ca_chua_discription/meshes/link_2.STL" />
      </geometry>
      <material
        name="">
        <color
          rgba="0.501960784313725 0.501960784313725 1 1" />
      </material>
    </visual>
    <collision>
      <origin
        xyz="0 0 0"
        rpy="0 0 0" />
      <geometry>
        <mesh
          filename="package://Ca_chua_discription/meshes/link_2.STL" />
      </geometry>
    </collision>
  </link>
  <joint
    name="joint_2"
    type="continuous">
    <origin
      xyz="0 -0.20072 0.012"
      rpy="0 0 -0.59257" />
    <parent
      link="link_1" />
    <child
      link="link_2" />
    <axis
      xyz="0 0 1" />
  </joint>
  <link
    name="link_3">
    <inertial>
      <origin
        xyz="-0.0131002977841246 -0.116411787180883 -0.0313135878540829"
        rpy="0 0 0" />
      <mass
        value="0.454304812581273" />
      <inertia
        ixx="0.00085773207578438"
        ixy="0.000901723301370522"
        ixz="-1.39997464163509E-18"
        iyy="0.00290983080828492"
        iyz="4.9673566200655E-19"
        izz="0.00352875533740883" />
    </inertial>
    <visual>
      <origin
        xyz="0 0 0"
        rpy="0 0 0" />
      <geometry>
        <mesh
          filename="package://Ca_chua_discription/meshes/link_3.STL" />
      </geometry>
      <material
        name="">
        <color
          rgba="0.501960784313725 0.501960784313725 1 1" />
      </material>
    </visual>
    <collision>
      <origin
        xyz="0 0 0"
        rpy="0 0 0" />
      <geometry>
        <mesh
          filename="package://Ca_chua_discription/meshes/link_3.STL" />
      </geometry>
    </collision>
  </link>
  <joint
    name="joint_3"
    type="continuous">
    <origin
      xyz="0 -0.25 0"
      rpy="0 0 -0.994433274533891" />
    <parent
      link="link_2" />
    <child
      link="link_3" />
    <axis
      xyz="0 0 1" />
  </joint>
</robot>